Workbook

Sheet Query 1x
A1: 2003 | B1: Weight | C1: Total_Execution_Time | D1: Execution_Count | E1: Mean_Execution_Time | F1: Std_Dev_Execution_Time | G1: Total_Execution_Percentage | H1: Actual_Rows
A2: QueryType
A3: 1 | B3: 0.603 | C3: 827.589 | D3: 569 | E3: 1.454462 | F3: 2.338846 | G3: 1.044841 | H3: 1
A4: 2 | B4: 0.2246 | C4: 45250.429 | D4: 235 | E4: 192.55502 | F4: 120.07904 | G4: 57.129185 | H4: 942.9
A5: 3 | B5: 0.0475 | C5: 8857.111 | D5: 45 | E5: 196.82469 | F5: 157.26191 | G5: 11.182204 | H5: 306
A6: 4 | B6: 0.114 | C6: 24271.597 | D6: 136 | E6: 178.46762 | F6: 143.37982 | G6: 30.643169 | H6: 269.7
A7: 5 | B7: 0.0109 | C7: 0.476 | D7: 15 | E7: 0.031733 | F7: 0.025004 | G7: 0.000601 | H7: 1
E8: =SUMPRODUCT(B3:B7,E3:E7) -> 73.819725 | H8: =SUMPRODUCT(B3:B7,H3:H7) -> 257.67004
A10: 2003 opt | B10: Weight | C10: Total_Execution_Time | D10: Execution_Count | E10: Mean_Execution_Time | F10: Std_Dev_Execution_Time | G10: Total_Execution_Percentage | H10: Actual_Rows
A11: QueryType
A12: 1 | B12: 0.603 | C12: 915.398 | D12: 586 | E12: 1.562113 | F12: 1.326388 | G12: 12.084563 | H12: 1
A13: 2 | B13: 0.2246 | C13: 2855.54 | D13: 248 | E13: 11.514274 | F13: 7.672408 | G13: 37.697211 | H13: 942.4
A14: 3 | B14: 0.0475 | C14: 1130.362 | D14: 42 | E14: 26.913381 | F14: 20.521537 | G14: 14.922395 | H14: 293.7
A15: 4 | B15: 0.114 | C15: 2672.638 | D15: 110 | E15: 24.296709 | F15: 19.526899 | G15: 35.282643 | H15: 270.2
A16: 5 | B16: 0.0109 | C16: 0.999 | D16: 14 | E16: 0.071357 | F16: 0.037963 | G16: 0.013188 | H16: 1
E17: =SUMPRODUCT(B12:B16,E12:E16) -> 7.5770483 | F17: =SQRT(SUMPRODUCT(B12:B16,F12:F16)/SUM(B12:B16)) -> 2.3925485 | H17: =SUMPRODUCT(B12:B16,H12:H16) -> 257.03049
H18: =AVERAGEIF(H12:H16,">1") -> 502.1
A19: 2013 over03opt | B19: Weight | C19: Total_Execution_Time | D19: Execution_Count | E19: Mean_Execution_Time | F19: Std_Dev_Execution_Time | G19: Total_Execution_Percentage | H19: Actual_Rows | J19: 2013 opt | K19: Weight | L19: Total_Execution_Time | M19: Execution_Count | N19: Mean_Execution_Time | O19: Std_Dev_Execution_Time | P19: Total_Execution_Percentage | Q19: Actual_Rows | S19: 2013 | T19: Weight | U19: Total_Execution_Time | V19: Execution_Count | W19: Mean_Execution_Time | X19: Std_Dev_Execution_Time | Y19: Total_Execution_Percentage | Z19: Actual_Rows
A20: QueryType | J20: QueryType | S20: QueryType
A21: 1 | B21: 0.1066 | C21: 1715.498 | D21: 1901 | E21: 9.02419e-07 | F21: 1.024013 | G21: 1.50641e-07 | H21: 1 | J21: 1 | K21: 0.1066 | L21: 34348.437 | M21: 18899 | N21: 1.817474 | O21: 1.229958 | P21: 11.845737 | Q21: 1 | S21: 1 | T21: 0.1066 | U21: 186490.68 | V21: 19009 | W21: 9.810652 | X21: 8.262563 | Y21: 3.732976 | Z21: 1
A22: 2 | B22: 0.0133 | C22: 2220.577 | D22: 251 | E22: 8.84692 | F22: 6.510342 | G22: 1.94993e-07 | H22: 1007 | J22: 2 | K22: 0.0133 | L22: 28142.873 | M22: 2349 | N22: 11.980789 | O22: 7.942078 | P22: 9.705626 | Q22: 559.2 | S22: 2 | T22: 0.0133 | U22: 813700.35 | V22: 2393 | W22: 340.03358 | X22: 195.24016 | Y22: 16.287808 | Z22: 945.8
A23: 3 | B23: 0.1413 | C23: 1132941.8 | D23: 2521 | E23: 449.40173 | F23: 250.91588 | G23: 99.485776 | H23: 418.3 | J23: 3 | K23: 0.1413 | L23: 159735.83 | M23: 25180 | N23: 6.343758 | O23: 3.454123 | P23: 55.088056 | Q23: 426.3 | S23: 3 | T23: 0.1413 | U23: 3975849.1 | V23: 25463 | W23: 156.14221 | X23: 89.084966 | Y23: 79.584414 | Z23: 414.6
A24: 4 | B24: 0.0547 | C24: 41.125 | D24: 982 | E24: 4.1879e-08 | F24: 2.9314e-08 | G24: 3.611e-09 | H24: 1 | J24: 4 | K24: 0.0547 | L24: 292.032 | M24: 9833 | N24: 2.9699e-08 | O24: 1.3224e-08 | P24: 1.00713e-07 | Q24: 1 | S24: 4 | T24: 0.0547 | U24: 201.389 | V24: 9802 | W24: 2.0546e-08 | X24: 1.1872e-08 | Y24: 4.031e-09 | Z24: 1
A25: 5 | B25: 0.0468 | C25: 23 | D25: 861 | E25: 2.6713e-08 | F25: 2.0212e-08 | G25: 2.02e-09 | H25: 0.16 | J25: 5 | K25: 0.0468 | L25: 8055.896 | M25: 8388 | N25: 9.60407e-07 | O25: 24.359742 | P25: 2.778235 | Q25: 0.17 | S25: 5 | T25: 0.0468 | U25: 100.319 | V25: 8352 | W25: 1.2011e-08 | X25: 7.861e-09 | Y25: 2.008e-09 | Z25: 0.16
A26: 6 | B26: 0.1078 | C26: 227.59 | D26: 1873 | E26: 1.21511e-07 | F26: 1.56227e-07 | G26: 1.9985e-08 | H26: 1 | J26: 6 | K26: 0.1078 | L26: 16143.956 | M26: 19448 | N26: 8.30109e-07 | O26: 13.875934 | P26: 5.567562 | Q26: 1 | S26: 6 | T26: 0.1078 | U26: 250.407 | V26: 19363 | W26: 1.2932e-08 | X26: 7.762e-09 | Y26: 5.012e-09 | Z26: 1
A27: 7 | B27: 0.0349 | C27: 17.433 | D27: 617 | E27: 2.8254e-08 | F27: 2.1227e-08 | G27: 1.531e-09 | H27: 4 | J27: 7 | K27: 0.0349 | L27: 12229.996 | M27: 6294 | N27: 1.94312 | O27: 28.418641 | P27: 4.217756 | Q27: 4 | S27: 7 | T27: 0.0349 | U27: 6654.247 | V27: 6217 | W27: 1.070331 | X27: 17.565949 | Y27: 1.33198e-07 | Z27: 4
A28: 8 | B28: 0.0263 | C28: 12.48 | D28: 498 | E28: 2.506e-08 | F28: 1.7746e-08 | G28: 1.096e-09 | H28: 1 | J28: 8 | K28: 0.0263 | L28: 147.201 | M28: 4807 | N28: 3.0622e-08 | O28: 1.3769e-08 | P28: 5.0765e-08 | Q28: 1 | S28: 8 | T28: 0.0263 | U28: 100.56 | V28: 4672 | W28: 2.1524e-08 | X28: 1.2088e-08 | Y28: 2.013e-09 | Z28: 1
A29: 9 | B29: 0.0273 | C29: 1598.268 | D29: 496 | E29: 3.222315 | F29: 2.479346 | G29: 1.40347e-07 | H29: 0.13 | J29: 9 | K29: 0.0273 | L29: 30868.318 | M29: 4802 | N29: 6.428221 | O29: 2.83814 | P29: 10.645549 | Q29: 0.08 | S29: 9 | T29: 0.0273 | U29: 12416.446 | V29: 4729 | W29: 2.625597 | X29: 1.622757 | Y29: 2.4854e-07 | Z29: 0.1
E30: =SUMPRODUCT(B21:B29,E21:E29) -> 63.706097 | F30: =SQRT(SUMPRODUCT(B21:B29,F21:F29)/SUM(B21:B29)) -> 7.9934955 | H30: =SUMPRODUCT(B21:B29,H21:H29) -> 72.944927 | N30: =SUMPRODUCT(K21:K29,N21:N29) -> 1.4927657 | O30: =SQRT(SUMPRODUCT(K21:K29,O21:O29)/SUM(K21:K29)) -> 2.8151024 | Q30: =SUMPRODUCT(K21:K29,Q21:Q29) -> 68.11869 | W30: =SUMPRODUCT(T21:T29,W21:W29) -> 27.74019 | Z30: =SUMPRODUCT(T21:T29,Z21:Z29) -> 71.607338
Z31: =AVERAGEIF(Z21:Z29,">1") -> 454.8
A32: 2023 over03opt | B32: Weight | C32: Total_Execution_Time | D32: Execution_Count | E32: Mean_Execution_Time | F32: Std_Dev_Execution_Time | G32: Total_Execution_Percentage | H32: Actual_Rows | J32: 2023 over13opt | K32: Weight | L32: Total_Execution_Time | M32: Execution_Count | N32: Mean_Execution_Time | O32: Std_Dev_Execution_Time | P32: Total_Execution_Percentage | Q32: Actual_Rows | S32: 2023 opt | T32: Weight | U32: Total_Execution_Time | V32: Execution_Count | W32: Mean_Execution_Time | X32: Std_Dev_Execution_Time | Y32: Total_Execution_Percentage | Z32: Actual_Rows | AB32: 2023 | AC32: Weight | AD32: Total_Execution_Time | AE32: Execution_Count | AF32: Mean_Execution_Time | AG32: Std_Dev_Execution_Time | AH32: Total_Execution_Percentage | AI32: Actual_Rows
A33: QueryType | J33: QueryType | S33: QueryType | AB33: QueryType
A34: 1 | B34: 0.0793 | C34: 7086.825 | D34: 794 | E34: 8.925472 | F34: 7.063757 | G34: 1.13449e-07 | H34: 937 | J34: 1 | K34: 0.0793 | L34: 292597.2 | M34: 846 | N34: 345.85958 | O34: 48.309656 | P34: 10.109639 | Q34: 953.2 | S34: 1 | T34: 0.0793 | U34: 10102.714 | V34: 822 | W34: 12.290406 | X34: 8.470029 | Y34: 1.364325 | Z34: 965.3 | AB34: 1 | AC34: 0.0793 | AD34: 60549.926 | AE34: 831 | AF34: 72.86393 | AG34: 42.566394 | AH34: 4.06583 | AI34: 191.2
A35: 2 | B35: 0.0616 | C35: 535.417 | D35: 616 | E35: 8.69183e-07 | F35: 9.31686e-07 | G35: 8.571e-09 | H35: 1 | J35: 2 | K35: 0.0616 | L35: 254.613 | M35: 607 | N35: 4.19461e-07 | O35: 4.58152e-07 | P35: 8.797e-09 | Q35: 1 | S35: 2 | T35: 0.0616 | U35: 733.521 | V35: 608 | W35: 1.206449 | X35: 1.443203 | Y35: 9.9059e-08 | Z35: 1 | AB35: 2 | AC35: 0.0616 | AD35: 2665.34 | AE35: 666 | AF35: 4.002012 | AG35: 2.918797 | AH35: 1.78973e-07 | AI35: 1
A36: 3 | B36: 0.0903 | C36: 112051.01 | D36: 956 | E36: 117.20817 | F36: 163.1556 | G36: 1.793762 | H36: 154.7 | J36: 3 | K36: 0.0903 | L36: 6078.994 | M36: 954 | N36: 6.372111 | O36: 6.073468 | P36: 2.10038e-07 | Q36: 2.5 | S36: 3 | T36: 0.0903 | U36: 46837.083 | V36: 863 | W36: 54.272402 | X36: 69.290691 | Y36: 6.325132 | Z36: 2.45 | AB36: 3 | AC36: 0.0903 | AD36: 18227.59 | AE36: 955 | AF36: 19.086482 | AG36: 25.383277 | AH36: 1.223953 | AI36: 29
A37: 4 | B37: 0.0767 | C37: 426870.79 | D37: 803 | E37: 531.595 | F37: 213.16259 | G37: 6.833536 | H37: 3746.4 | J37: 4 | K37: 0.0767 | L37: 99561.641 | M37: 807 | N37: 123.37254 | O37: 296.18137 | P37: 3.439993 | Q37: 3842.7 | S37: 4 | T37: 0.0767 | U37: 3620.016 | V37: 829 | W37: 4.366726 | X37: 9.799337 | Y37: 4.88866e-07 | Z37: 3283 | AB37: 4 | AC37: 0.0767 | AD37: 393686.36 | AE37: 761 | AF37: 517.32767 | AG37: 208.58053 | AH37: 26.435405 | AI37: 3488.2
A38: 5 | B38: 0.0142 | C38: 4.931 | D38: 139 | E38: 3.5475e-08 | F38: 2.7178e-08 | G38: 7.9e-11 | H38: 0.17 | J38: 5 | K38: 0.0142 | L38: 5.316 | M38: 142 | N38: 3.7437e-08 | O38: 2.3384e-08 | P38: 1.84e-10 | Q38: 0.18 | S38: 5 | T38: 0.0142 | U38: 3.429 | V38: 148 | W38: 2.3169e-08 | X38: 1.6194e-08 | Y38: 4.63e-10 | Z38: 0 | AB38: 5 | AC38: 0.0142 | AD38: 1.722 | AE38: 154 | AF38: 1.1182e-08 | AG38: 4.763e-09 | AH38: 1.16e-10 | AI38: 0.01
A39: 6 | B39: 0.3801 | C39: 636.737 | D39: 3886 | E39: 1.63854e-07 | F39: 1.65946e-07 | G39: 1.0193e-08 | H39: 1 | J39: 6 | K39: 0.3801 | L39: 757.434 | M39: 3964 | N39: 1.91078e-07 | O39: 1.69283e-07 | P39: 2.617e-08 | Q39: 1 | S39: 6 | T39: 0.3801 | U39: 938.975 | V39: 4079 | W39: 2.30197e-07 | X39: 1.72634e-07 | Y39: 1.26804e-07 | Z39: 1 | AB39: 6 | AC39: 0.3801 | AD39: 165.273 | AE39: 4047 | AF39: 4.0838e-08 | AG39: 6.4435e-08 | AH39: 1.1098e-08 | AI39: 1
A40: 7 | B40: 0.0453 | C40: 4786249.9 | D40: 483 | E40: 9909.4201 | F40: 4050.8229 | G40: 76.620407 | H40: 8715.8 | J40: 7 | K40: 0.0453 | L40: 1812630.3 | M40: 496 | N40: 3654.4965 | O40: 1364.9548 | P40: 62.628891 | Q40: 9241 | S40: 7 | T40: 0.0453 | U40: 254725.17 | V40: 463 | W40: 550.16236 | X40: 983.88583 | Y40: 34.399461 | Z40: 9669 | AB40: 7 | AC40: 0.0453 | AD40: 692063.42 | AE40: 451 | AF40: 1534.5087 | AG40: 2174.2692 | AH40: 46.470943 | AI40: 10176.4
A41: 8 | B41: 0.082 | C41: 173.809 | D41: 895 | E41: 1.942e-07 | F41: 2.08083e-07 | G41: 2.782e-09 | H41: 0.64 | J41: 8 | K41: 0.082 | L41: 153.707 | M41: 902 | N41: 1.70407e-07 | O41: 1.5755e-07 | P41: 5.311e-09 | Q41: 0.64 | S41: 8 | T41: 0.082 | U41: 183.233 | V41: 858 | W41: 2.13558e-07 | X41: 1.80992e-07 | Y41: 2.4745e-08 | Z41: 0.64 | AB41: 8 | AC41: 0.082 | AD41: 14.778 | AE41: 804 | AF41: 1.8381e-08 | AG41: 1.9748e-08 | AH41: 9.92e-10 | AI41: 0.13
...

Sheet Mig 1x
A1: W | C1: Query volume | D1: Original query volume
A2: alpha | C2: 10000 | D2: 50333
A3: beta | C3: 10000 | D3: 1489126
A4: gamma | C4: 10000 | D4: 3623390
A6: W beta (2013) | B6: Avg q time | C6: Total time (sec) on query volume | D6: Total time (sec) on original query volume | F6: Total time (min) on query volume | G6: Total time (min) on original query volume | K6: Mig time (sec) from alpha | L6: Scaled (sec) | M6: Scaled (min) | N6: Scaled (h) | O6: Scaled (d)
A7: D2_alpha | B7: ='Query 1x'!E30 -> 63.706097 | C7: =$B7*C$3/1000 -> 637.06097 | D7: =$B7*D$3/1000 -> 94866.406 | F7: =C7/60 -> 10.617683 | G7: =D7/60 -> 1581.1068
A8: D2_beta | B8: ='Query 1x'!N30 -> 1.4927657 | C8: =$B8*C$3/1000 -> 14.927657 | D8: =$B8*D$3/1000 -> 2222.9162 | F8: =C8/60 -> 0.24879428 | G8: =D8/60 -> 37.048603 | K8: 55.1 | L8: =K8*$D$24 -> 678281 | M8: =L8/60 -> 11304.683 | N8: =M8/60 -> 188.41139 | O8: =N8/24 -> 7.8504745
A10: W gamma (2023) | B10: Avg q time | C10: Total time (sec) on query volume | D10: Total time (sec) on original query volume | F10: Total time (min) on query volume | G10: Total time (min) on original query volume | H10: Total time (h) on original query volume | I10: Total time (d) on original query volume | K10: Mig time (sec) from beta | L10: Scaled (sec) | M10: Scaled (min) | N10: Scaled (h) | O10: Scaled (d)
A11: D3_alpha | B11: ='Query 1x'!E49 -> 571.1808 | C11: =$B11*C$4/1000 -> 5711.808 | D11: =$B11*D$4/1000 -> 2069610.8 | F11: =C11/60 -> 95.1968 | G11: =D11/60 -> 34493.513 | H11: =G11/60 -> 574.89189 | I11: =H11/24 -> 23.953829
A12: D3_beta | B12: ='Query 1x'!N49 -> 269.71696 | C12: =$B12*C$4/1000 -> 2697.1696 | D12: =$B12*D$4/1000 -> 977289.73 | F12: =C12/60 -> 44.952826 | G12: =D12/60 -> 16288.162 | H12: =G12/60 -> 271.46937 | I12: =H12/24 -> 11.311224
A13: D3_gamma | B13: ='Query 1x'!W49 -> 66.730691 | C13: =$B13*C$4/1000 -> 667.30691 | D13: =$B13*D$4/1000 -> 241791.32 | F13: =C13/60 -> 11.121782 | G13: =D13/60 -> 4029.8553 | H13: =G13/60 -> 67.164256 | I13: =H13/24 -> 2.7985106 | K13: 93 | L13: =K13*$D$24 -> 1144830 | M13: =L13/60 -> 19080.5 | N13: =M13/60 -> 318.00833 | O13: =N13/24 -> 13.250347
A23: Table | B23: Original card | C23: Sample card | D23: Rate
A24: PhotoObjAll | B24: 1231000000 | C24: 100000 | D24: =B24/C24 -> 12310

Sheet Query 2x
A1: 2003 | B1: Weight | C1: Total_Execution_Time | D1: Execution_Count | E1: Mean_Execution_Time | F1: Std_Dev_Execution_Time | G1: Total_Execution_Percentage
A2: QueryType
A3: 1 | B3: 0.603 | C3: 422.074 | D3: 606 | E3: 6.96492e-07 | F3: 5.14922e-07 | G3: 5.99454e-07
A4: 2 | B4: 0.2246 | C4: 37755.193 | D4: 229 | E4: 164.86984 | F4: 81.929844 | G4: 53.622111
A5: 3 | B5: 0.0475 | C5: 9367.606 | D5: 44 | E5: 212.90014 | F5: 158.20356 | G5: 13.304417
A6: 4 | B6: 0.114 | C6: 22864.569 | D6: 108 | E6: 211.70897 | F6: 153.71595 | G6: 32.473585
A7: 5 | B7: 0.0109 | C7: 0.000305 | D7: 13 | E7: 2.3462e-08 | F7: 1.1949e-08 | G7: 4.33e-10
E8: =SUMPRODUCT(B3:B7,E3:E7) -> 71.277345
A10: 2003 opt | B10: Weight | C10: Total_Execution_Time | D10: Execution_Count | E10: Mean_Execution_Time | F10: Std_Dev_Execution_Time | G10: Total_Execution_Percentage
A11: QueryType
A12: 1 | B12: 0.603 | C12: 617.276 | D12: 623 | E12: 9.90812e-07 | F12: 9.06839e-07 | G12: 10.401206
A13: 2 | B13: 0.2246 | C13: 1902.608 | D13: 187 | E13: 10.174374 | F13: 8.987102 | G13: 32.059269
A14: 3 | B14: 0.0475 | C14: 768.805 | D14: 54 | E14: 14.23713 | F14: 19.181145 | G14: 12.954495
A15: 4 | B15: 0.114 | C15: 2645.376 | D15: 122 | E15: 21.68341 | F15: 20.490526 | G15: 44.575037
A16: 5 | B16: 0.0109 | C16: 0.000593 | D16: 14 | E16: 4.2357e-08 | F16: 2.2687e-08 | G16: 9.992e-09
E17: =SUMPRODUCT(B12:B16,E12:E16) -> 5.4333374 | F17: =SQRT(SUMPRODUCT(B12:B16,F12:F16)/SUM(B12:B16)) -> 2.2946738
A19: 2013 over03opt | B19: Weight | C19: Total_Execution_Time | D19: Execution_Count | E19: Mean_Execution_Time | F19: Std_Dev_Execution_Time | G19: Total_Execution_Percentage | I19: 2013 opt | J19: Weight | K19: Total_Execution_Time | L19: Execution_Count | M19: Mean_Execution_Time | N19: Std_Dev_Execution_Time | O19: Total_Execution_Percentage | Q19: 2013 | R19: Weight | S19: Total_Execution_Time | T19: Execution_Count | U19: Mean_Execution_Time | V19: Std_Dev_Execution_Time | W19: Total_Execution_Percentage
A20: QueryType | I20: QueryType | Q20: QueryType
A21: 1 | B21: 0.1066 | C21: 1250.309 | D21: 1925 | E21: 6.49511e-07 | F21: 7.15663e-07 | G21: 1.17152e-07 | I21: 1 | J21: 0.1066 | K21: 1601.902 | L21: 1942 | M21: 8.24872e-07 | N21: 4.84482e-07 | O21: 5.641093 | Q21: 1 | R21: 0.1066 | S21: 1212.402 | T21: 1940 | U21: 6.24949e-07 | V21: 4.47472e-07 | W21: 2.48188e-07
A22: 2 | B22: 0.0133 | C22: 2465.773 | D22: 224 | E22: 11.007915 | F22: 9.422103 | G22: 2.31039e-07 | I22: 2 | J22: 0.0133 | K22: 3550.286 | L22: 206 | M22: 17.234398 | N22: 8.62659 | O22: 12.502321 | Q22: 2 | R22: 0.0133 | S22: 64886.811 | T22: 228 | U22: 284.59128 | V22: 132.45937 | W22: 13.28285
A23: 3 | B23: 0.1413 | C23: 1050905.9 | D23: 2501 | E23: 420.19428 | F23: 225.00731 | G23: 98.468305 | I23: 3 | J23: 0.1413 | K23: 18066.354 | L23: 2579 | M23: 7.005178 | N23: 3.987335 | O23: 63.620607 | Q23: 3 | R23: 0.1413 | S23: 422313.88 | T23: 2654 | U23: 159.12354 | V23: 89.085866 | W23: 86.451036
A24: 4 | B24: 0.0547 | C24: 806.488 | D24: 961 | E24: 8.39217e-07 | F24: 20.694286 | G24: 7.5567e-08 | I24: 4 | J24: 0.0547 | K24: 129.659 | L24: 951 | M24: 1.3634e-07 | N24: 1.144816 | O24: 4.56594e-07 | Q24: 4 | R24: 0.0547 | S24: 20.693 | T24: 979 | U24: 2.1137e-08 | V24: 1.2507e-08 | W24: 4.236e-09
A25: 5 | B25: 0.0468 | C25: 22.492 | D25: 826 | E25: 2.723e-08 | F25: 1.9897e-08 | G25: 2.107e-09 | I25: 5 | J25: 0.0468 | K25: 565.203 | L25: 808 | M25: 6.99509e-07 | N25: 3.784601 | O25: 1.990361 | Q25: 5 | R25: 0.0468 | S25: 8.91 | T25: 788 | U25: 1.1307e-08 | V25: 6.631e-09 | W25: 1.824e-09
A26: 6 | B26: 0.1078 | C26: 4326.369 | D26: 1992 | E26: 2.171872 | F26: 34.158247 | G26: 4.05374e-07 | I26: 6 | J26: 0.1078 | K26: 3339.291 | L26: 1939 | M26: 1.722172 | N26: 7.584774 | O26: 11.759302 | Q26: 6 | R26: 0.1078 | S26: 26.081 | T26: 1888 | U26: 1.3814e-08 | V26: 7.466e-09 | W26: 5.339e-09
A27: 7 | B27: 0.0349 | C27: 6284.999 | D27: 617 | E27: 10.186384 | F27: 64.420384 | G27: 5.88895e-07 | I27: 7 | J27: 0.0349 | K27: 849.844 | L27: 599 | M27: 1.418771 | N27: 6.423758 | O27: 2.992723 | Q27: 7 | R27: 0.0349 | S27: 12.557 | T27: 580 | U27: 2.165e-08 | V27: 1.1171e-08 | W27: 2.571e-09
A28: 8 | B28: 0.0263 | C28: 10.929 | D28: 464 | E28: 2.3554e-08 | F28: 1.5492e-08 | G28: 1.024e-09 | I28: 8 | J28: 0.0263 | K28: 75.559 | L28: 468 | M28: 1.61451e-07 | N28: 1.564007 | O28: 2.66081e-07 | Q28: 8 | R28: 0.0263 | S28: 9.262 | T28: 450 | U28: 2.0582e-08 | V28: 1.0417e-08 | W28: 1.896e-09
A29: 9 | B29: 0.0273 | C29: 1179.698 | D29: 490 | E29: 2.407547 | F29: 25.608864 | G29: 1.10536e-07 | I29: 9 | J29: 0.0273 | K29: 218.918 | L29: 508 | M29: 4.30941e-07 | N29: 2.76023 | O29: 7.70919e-07 | Q29: 9 | R29: 0.0273 | S29: 10.063 | T29: 493 | U29: 2.0412e-08 | V29: 1.09e-08 | W29: 2.06e-09
E30: =SUMPRODUCT(B21:B29,E21:E29) -> 60.175215 | M30: =SUMPRODUCT(J21:J29,M21:M29) -> 1.4542145 | N30: =SQRT(SUMPRODUCT(J21:J29,N21:N29)/SUM(J21:J29)) -> 1.9272086 | U30: =SUMPRODUCT(R21:R29,U21:U29) -> 26.269221
A32: 2023 over03opt | B32: Weight | C32: Total_Execution_Time | D32: Execution_Count | E32: Mean_Execution_Time | F32: Std_Dev_Execution_Time | G32: Total_Execution_Percentage | I32: 2023 over13opt | J32: Weight | K32: Total_Execution_Time | L32: Execution_Count | M32: Mean_Execution_Time | N32: Std_Dev_Execution_Time | O32: Total_Execution_Percentage | Q32: 2023 opt | R32: Weight | S32: Total_Execution_Time | T32: Execution_Count | U32: Mean_Execution_Time | V32: Std_Dev_Execution_Time | W32: Total_Execution_Percentage | Y32: 2023 | Z32: Weight | AA32: Total_Execution_Time | AB32: Execution_Count | AC32: Mean_Execution_Time | AD32: Std_Dev_Execution_Time | AE32: Total_Execution_Percentage
A33: QueryType | I33: QueryType | Q33: QueryType | Y33: QueryType
A34: 1 | B34: 0.0793 | C34: 677.265 | D34: 65 | E34: 10.419462 | F34: 8.283594 | G34: 6.5806e-08 | I34: 1 | J34: 0.0793 | K34: 51899.985 | L34: 75 | M34: 691.9998 | N34: 81.663265 | O34: 9.429658 | Q34: 1 | R34: 0.0793 | S34: 1458.091 | T34: 80 | U34: 18.226138 | V34: 12.761842 | W34: 2.915959 | Y34: 1 | Z34: 0.0793 | AA34: 259934.42 | AB34: 901 | AC34: 288.49547 | AD34: 140.06092 | AE34: 9.010777
A35: 2 | B35: 0.0616 | C35: 32.441 | D35: 67 | E35: 4.84194e-07 | F35: 4.72741e-07 | G35: 3.152e-09 | I35: 2 | J35: 0.0616 | K35: 19.242 | L35: 71 | M35: 2.71014e-07 | N35: 5.61402e-07 | O35: 3.496e-09 | Q35: 2 | R35: 0.0616 | S35: 39.311 | T35: 69 | U35: 5.69725e-07 | V35: 4.786e-07 | W35: 7.8616e-08 | Y35: 2 | Z35: 0.0616 | AA35: 385.494 | AB35: 631 | AC35: 6.10926e-07 | AD35: 4.52353e-07 | AE35: 1.3363e-08
A36: 3 | B36: 0.0903 | C36: 24951.17 | D36: 98 | E36: 254.60378 | F36: 356.67767 | G36: 2.42437 | I36: 3 | J36: 0.0903 | K36: 1580.196 | L36: 100 | M36: 15.80196 | N36: 15.437245 | O36: 2.87104e-07 | Q36: 3 | R36: 0.0903 | S36: 12340.065 | T36: 115 | U36: 107.30491 | V36: 145.87513 | W36: 24.678239 | Y36: 3 | Z36: 0.0903 | AA36: 51349.297 | AB36: 918 | AC36: 55.936053 | AD36: 108.34359 | AE36: 1.780053
A37: 4 | B37: 0.0767 | C37: 82973.377 | D37: 84 | E37: 987.7783 | F37: 334.42308 | G37: 8.062073 | I37: 4 | J37: 0.0767 | K37: 23499.771 | L37: 79 | M37: 297.46546 | N37: 671.28153 | O37: 4.269651 | Q37: 4 | R37: 0.0767 | S37: 521.716 | T37: 75 | U37: 6.956213 | V37: 14.32982 | W37: 1.043352 | Y37: 4 | Z37: 0.0767 | AA37: 807973.76 | AB37: 766 | AC37: 1054.796 | AD37: 401.76835 | AE37: 28.008879
A38: 5 | B38: 0.0142 | C38: 0.000408 | D38: 14 | E38: 2.9143e-08 | F38: 5.559e-09 | G38: 4e-11 | I38: 5 | J38: 0.0142 | K38: 0.000385 | L38: 13 | M38: 2.9615e-08 | N38: 8.588e-09 | O38: 7e-11 | Q38: 5 | R38: 0.0142 | S38: 0.000474 | T38: 16 | U38: 2.9625e-08 | V38: 2.3799e-08 | W38: 9.48e-10 | Y38: 5 | Z38: 0.0142 | AA38: 2.529 | AB38: 148 | AC38: 1.7088e-08 | AD38: 1.0876e-08 | AE38: 8.8e-11
A39: 6 | B39: 0.3801 | C39: 54.574 | D39: 415 | E39: 1.31504e-07 | F39: 1.13769e-07 | G39: 5.303e-09 | I39: 6 | J39: 0.3801 | K39: 70.577 | L39: 389 | M39: 1.81432e-07 | N39: 1.6826e-07 | O39: 1.2823e-08 | Q39: 6 | R39: 0.3801 | S39: 83.435 | T39: 390 | U39: 2.13936e-07 | V39: 1.78529e-07 | W39: 1.66857e-07 | Y39: 6 | Z39: 0.3801 | AA39: 683.841 | AB39: 4032 | AC39: 1.69603e-07 | AD39: 9.9705e-08 | AE39: 2.3706e-08
A40: 7 | B40: 0.0453 | C40: 772960.28 | D40: 40 | E40: 19324.007 | F40: 7442.7858 | G40: 75.104357 | I40: 7 | J40: 0.0453 | K40: 358213.61 | L40: 53 | M40: 6758.7473 | N40: 2403.9389 | O40: 65.083482 | Q40: 7 | R40: 0.0453 | S40: 18131.53 | T40: 48 | U40: 377.74021 | V40: 782.17475 | W40: 36.260281 | Y40: 7 | Z40: 0.0453 | AA40: 1199798.9 | AB40: 446 | AC40: 2690.132 | AD40: 3691.9875 | AE40: 41.591723
A41: 8 | B41: 0.082 | C41: 11.648 | D41: 77 | E41: 1.51273e-07 | F41: 1.01089e-07 | G41: 1.132e-09 | I41: 8 | J41: 0.082 | K41: 13.765 | L41: 78 | M41: 1.76474e-07 | N41: 1.83536e-07 | O41: 2.501e-09 | Q41: 8 | R41: 0.082 | S41: 15.607 | T41: 75 | U41: 2.08093e-07 | V41: 1.61963e-07 | W41: 3.1212e-08 | Y41: 8 | Z41: 0.082 | AA41: 48.006 | AB41: 832 | AC41: 5.77e-08 | AD41: 3.0587e-08 | AE41: 1.664e-09
A42: 9 | B42: 0.0061 | C42: 14899.731 | D42: 5 | E42: 2979.9462 | F42: 728.64028 | G42: 1.447726 | I42: 9 | J42: 0.0061 | K42: 21543.946 | L42: 6 | M42: 3590.6577 | N42: 1168.2414 | O42: 3.914299 | Q42: 9 | R42: 0.0061 | S42: 2542.03 | T42: 10 | U42: 254.203 | V42: 641.07768 | W42: 5.08367 | Y42: 9 | Z42: 0.0061 | AA42: 101159.7 | AB42: 69 | AC42: 1466.0826 | AD42: 2389.0299 | AE42: 3.50676
A43: 10 | B43: 0.0055 | C43: 12877.596 | D43: 5 | E43: 2575.5192 | F43: 384.58792 | G43: 1.251246 | I43: 10 | J43: 0.0055 | K43: 16404.586 | L43: 5 | M43: 3280.9172 | N43: 964.41264 | O43: 2.980533 | Q43: 10 | R43: 0.0055 | S43: 158.011 | T43: 4 | U43: 39.50275 | V43: 16.66794 | W43: 3.15998e-07 | Y43: 10 | Z43: 0.0055 | AA43: 48440.344 | AB43: 74 | AC43: 654.59924 | AD43: 473.79764 | AE43: 1.679213
...

Sheet Mig 2x
A1: W | C1: Query volume | D1: Original query volume
A2: alpha | C2: 10000 | D2: 50333
A3: beta | C3: 10000 | D3: 1489126
A4: gamma | C4: 10000 | D4: 3623390
A6: W beta (2013) | B6: Avg q time | C6: Total time (sec) on query volume | D6: Total time (sec) on original query volume | F6: Total time (min) on query volume | G6: Total time (min) on original query volume | K6: Mig time (sec) from D1_alpha | L6: Scaled (sec) | M6: Scaled (min) | N6: Scaled (h) | O6: Scaled (d)
A7: D2_alpha | B7: ='Query 2x'!E30 -> 60.175215 | C7: =$B7*C$3/1000 -> 601.75215 | D7: =$B7*D$3/1000 -> 89608.477 | F7: =C7/60 -> 10.029203 | G7: =D7/60 -> 1493.4746
A8: D2_beta | B8: ='Query 2x'!M30 -> 1.4542145 | C8: =$B8*C$3/1000 -> 14.542145 | D8: =$B8*D$3/1000 -> 2165.5087 | F8: =C8/60 -> 0.24236909 | G8: =D8/60 -> 36.091811 | K8: 127.1 | L8: =K8*$D$24 -> 782300.5 | M8: =L8/60 -> 13038.342 | N8: =M8/60 -> 217.30569 | O8: =N8/24 -> 9.0544039
A10: W gamma (2023) | B10: Avg q time | C10: Total time (sec) on query volume | D10: Total time (sec) on original query volume | F10: Total time (min) on query volume | G10: Total time (min) on original query volume | H10: Total time (h) on original query volume | I10: Total time (d) on original query volume | K10: Mig time (sec) from D2_beta | L10: Scaled (sec) | M10: Scaled (min) | N10: Scaled (h) | O10: Scaled (d)
A11: D3_alpha | B11: ='Query 2x'!E49 -> 1124.4442 | C11: =$B11*C$4/1000 -> 11244.442 | D11: =$B11*D$4/1000 -> 4074300 | F11: =C11/60 -> 187.40737 | G11: =D11/60 -> 67905 | H11: =G11/60 -> 1131.75 | I11: =H11/24 -> 47.15625
A12: D3_beta | B12: ='Query 2x'!M49 -> 490.92731 | C12: =$B12*C$4/1000 -> 4909.2731 | D12: =$B12*D$4/1000 -> 1778821.1 | F12: =C12/60 -> 81.821218 | G12: =D12/60 -> 29647.018 | H12: =G12/60 -> 494.11697 | I12: =H12/24 -> 20.588207
A13: D3_gamma | B13: ='Query 2x'!U49 -> 45.527085 | C13: =$B13*C$4/1000 -> 455.27085 | D13: =$B13*D$4/1000 -> 164962.38 | F13: =C13/60 -> 7.5878475 | G13: =D13/60 -> 2749.3731 | H13: =G13/60 -> 45.822885 | I13: =H13/24 -> 1.9092869 | K13: 233.3 | L13: =K13*$D$24 -> 1435961.5 | M13: =L13/60 -> 23932.692 | N13: =M13/60 -> 398.87819 | O13: =N13/24 -> 16.619925
A23: Table | B23: Original card | C23: Sample card | D23: Rate
A24: PhotoObjAll | B24: 1231000000 | C24: 200000 | D24: =B24/C24 -> 6155

Sheet Query 5x
A1: 2003 | B1: Weight | C1: Total_Execution_Time | D1: Execution_Count | E1: Mean_Execution_Time | F1: Std_Dev_Execution_Time | G1: Total_Execution_Percentage
A2: QueryType
A3: 1 | B3: 0.603 | C3: 11766.534 | D3: 6036 | E3: 1.949393 | F3: 1.900345 | G3: 1.827869
A4: 2 | B4: 0.2246 | C4: 273720.29 | D4: 2233 | E4: 122.57962 | F4: 47.309742 | G4: 42.52101
A5: 3 | B5: 0.0475 | C5: 105330.6 | D5: 471 | E5: 223.63185 | F5: 149.71258 | G5: 16.362556
A6: 4 | B6: 0.114 | C6: 252908.95 | D6: 1149 | E6: 220.11223 | F6: 148.48736 | G6: 39.288078
A7: 5 | B7: 0.0109 | C7: 3.128 | D7: 111 | E7: 2.818e-08 | F7: 1.6517e-08 | G7: 4.86e-10
E8: =SUMPRODUCT(B3:B7,E3:E7) -> 64.422173
A10: 2003 opt | B10: Weight | C10: Total_Execution_Time | D10: Execution_Count | E10: Mean_Execution_Time | F10: Std_Dev_Execution_Time | G10: Total_Execution_Percentage
A11: QueryType
A12: 1 | B12: 0.603 | C12: 4990.027 | D12: 6104 | E12: 8.17501e-07 | F12: 7.05291e-07 | G12: 9.224568
A13: 2 | B13: 0.2246 | C13: 16426.294 | D13: 2165 | E13: 7.587203 | F13: 5.225244 | G13: 30.365662
A14: 3 | B14: 0.0475 | C14: 9779.892 | D14: 489 | E14: 19.999779 | F14: 21.725108 | G14: 18.079117
A15: 4 | B15: 0.114 | C15: 22893.451 | D15: 1119 | E15: 20.458848 | F15: 19.964324 | G15: 42.320854
A16: 5 | B16: 0.0109 | C16: 5.3 | D16: 123 | E16: 4.3089e-08 | F16: 2.0423e-08 | G16: 9.798e-09
E17: =SUMPRODUCT(B12:B16,E12:E16) -> 4.9863845 | F17: =SQRT(SUMPRODUCT(B12:B16,F12:F16)/SUM(B12:B16)) -> 2.1169473
A19: 2013 over03opt | B19: Weight | C19: Total_Execution_Time | D19: Execution_Count | E19: Mean_Execution_Time | F19: Std_Dev_Execution_Time | G19: Total_Execution_Percentage | I19: 2013 opt | J19: Weight | K19: Total_Execution_Time | L19: Execution_Count | M19: Mean_Execution_Time | N19: Std_Dev_Execution_Time | O19: Total_Execution_Percentage | Q19: 2013 | R19: Weight | S19: Total_Execution_Time | T19: Execution_Count | U19: Mean_Execution_Time | V19: Std_Dev_Execution_Time | W19: Total_Execution_Percentage
A20: QueryType | I20: QueryType | Q20: QueryType
A21: 1 | B21: 0.1066 | C21: 1058.272 | D21: 1916 | E21: 5.52334e-07 | F21: 5.48341e-07 | G21: 9.2299e-08 | I21: 1 | J21: 0.1066 | K21: 1722.325 | L21: 1997 | M21: 8.62456e-07 | N21: 5.15562e-07 | O21: 4.749494 | Q21: 1 | R21: 0.1066 | S21: 3823.868 | T21: 1953 | U21: 1.957946 | V21: 2.062021 | W21: 8.6012e-07
A22: 2 | B22: 0.0133 | C22: 1466 | D22: 209 | E22: 7.014354 | F22: 5.193895 | G22: 1.2786e-07 | I22: 2 | J22: 0.0133 | K22: 6022.419 | L22: 261 | M22: 23.074402 | N22: 12.227681 | O22: 16.607459 | Q22: 2 | R22: 0.0133 | S22: 45594.711 | T22: 225 | U22: 202.64316 | V22: 81.587409 | W22: 10.255823
A23: 3 | B23: 0.1413 | C23: 1143762 | D23: 2583 | E23: 442.8037 | F23: 253.03289 | G23: 99.755308 | I23: 3 | J23: 0.1413 | K23: 26718.796 | L23: 2483 | M23: 10.760691 | N23: 8.914486 | O23: 73.679915 | Q23: 3 | R23: 0.1413 | S23: 394366.02 | T23: 2462 | U23: 160.18116 | V23: 91.95865 | W23: 88.70652
A24: 4 | B24: 0.0547 | C24: 35.202 | D24: 986 | E24: 3.5702e-08 | F24: 1.8846e-08 | G24: 3.07e-09 | I24: 4 | J24: 0.0547 | K24: 195.636 | L24: 948 | M24: 2.06367e-07 | N24: 5.008661 | O24: 5.39487e-07 | Q24: 4 | R24: 0.0547 | S24: 603.856 | T24: 929 | U24: 6.50006e-07 | V24: 10.756586 | W24: 1.35828e-07
A25: 5 | B25: 0.0468 | C25: 20.299 | D25: 844 | E25: 2.4051e-08 | F25: 1.3055e-08 | G25: 1.77e-09 | I25: 5 | J25: 0.0468 | K25: 1401.698 | L25: 826 | M25: 1.696971 | N25: 26.132982 | O25: 3.865331 | Q25: 5 | R25: 0.0468 | S25: 10.671 | T25: 841 | U25: 1.2688e-08 | V25: 8.163e-09 | W25: 2.4e-09
A26: 6 | B26: 0.1078 | C26: 190.516 | D26: 1892 | E26: 1.00696e-07 | F26: 1.01388e-07 | G26: 1.6616e-08 | I26: 6 | J26: 0.1078 | K26: 163.416 | L26: 1887 | M26: 8.6601e-08 | N26: 6.31219e-07 | O26: 4.50637e-07 | Q26: 6 | R26: 0.1078 | S26: 33.809 | T26: 2036 | U26: 1.6606e-08 | V26: 1.0132e-08 | W26: 7.605e-09
A27: 7 | B27: 0.0349 | C27: 14.06 | D27: 624 | E27: 2.2532e-08 | F27: 1.253e-08 | G27: 1.226e-09 | I27: 7 | J27: 0.0349 | K27: 16.239 | L27: 599 | M27: 2.711e-08 | N27: 1.4146e-08 | O27: 4.4781e-08 | Q27: 7 | R27: 0.0349 | S27: 106.977 | T27: 634 | U27: 1.68733e-07 | V27: 3.608563 | W27: 2.4063e-08
A28: 8 | B28: 0.0263 | C28: 10.529 | D28: 496 | E28: 2.1228e-08 | F28: 1.1704e-08 | G28: 9.18e-10 | I28: 8 | J28: 0.0263 | K28: 9.414 | L28: 506 | M28: 1.8605e-08 | N28: 9.352e-09 | O28: 2.596e-08 | Q28: 8 | R28: 0.0263 | S28: 9.624 | T28: 454 | U28: 2.1198e-08 | V28: 1.0985e-08 | W28: 2.165e-09
A29: 9 | B29: 0.0273 | C29: 10.679 | D29: 450 | E29: 2.3731e-08 | F29: 1.2948e-08 | G29: 9.31e-10 | I29: 9 | J29: 0.0273 | K29: 13.394 | L29: 493 | M29: 2.7168e-08 | N29: 2.9566e-08 | O29: 3.6935e-08 | Q29: 9 | R29: 0.0273 | S29: 24.348 | T29: 466 | U29: 5.2249e-08 | V29: 1.21956e-07 | W29: 5.477e-09
E30: =SUMPRODUCT(B21:B29,E21:E29) -> 62.661454 | M30: =SUMPRODUCT(J21:J29,M21:M29) -> 1.9067935 | N30: =SQRT(SUMPRODUCT(J21:J29,N21:N29)/SUM(J21:J29)) -> 2.2852261 | U30: =SUMPRODUCT(R21:R29,U21:U29) -> 25.537469
A32: 2023 over03opt | B32: Weight | C32: Total_Execution_Time | D32: Execution_Count | E32: Mean_Execution_Time | F32: Std_Dev_Execution_Time | G32: Total_Execution_Percentage | I32: 2023 over13opt | J32: Weight | K32: Total_Execution_Time | L32: Execution_Count | M32: Mean_Execution_Time | N32: Std_Dev_Execution_Time | O32: Total_Execution_Percentage | Q32: 2023 opt | R32: Weight | S32: Total_Execution_Time | T32: Execution_Count | U32: Mean_Execution_Time | V32: Std_Dev_Execution_Time | W32: Total_Execution_Percentage | Y32: 2023 | Z32: Weight | AA32: Total_Execution_Time | AB32: Execution_Count | AC32: Mean_Execution_Time | AD32: Std_Dev_Execution_Time | AE32: Total_Execution_Percentage
A33: QueryType | I33: QueryType | Q33: QueryType | Y33: QueryType
A34: 1 | B34: 0.0793 | C34: 6487699 | D34: 833 | E34: 7.788354 | F34: 9.510759 | G34: 4.0686e-08 | I34: 1 | J34: 0.0793 | K34: 528020.22 | L34: 840 | M34: 628.5955 | N34: 812.84328 | O34: 4.342856 | Q34: 1 | R34: 0.0793 | S34: 16172.704 | T34: 792 | U34: 20.420081 | V34: 10.4303 | W34: 1.213602 | Y34: 1 | Z34: 0.0793 | AA34: 171503.08 | AB34: 839 | AC34: 204.41369 | AD34: 81.219212 | AE34: 2.28833
A35: 2 | B35: 0.0616 | C35: 391568 | D35: 670 | E35: 5.8443e-07 | F35: 5.91128e-07 | G35: 2.456e-09 | I35: 2 | J35: 0.0616 | K35: 377.517 | L35: 656 | M35: 5.75483e-07 | N35: 4.06736e-07 | O35: 3.105e-09 | Q35: 2 | R35: 0.0616 | S35: 553.832 | T35: 676 | U35: 8.19278e-07 | V35: 5.86053e-07 | W35: 4.156e-08 | Y35: 2 | Z35: 0.0616 | AA35: 1175.172 | AB35: 661 | AC35: 1.77787 | AD35: 1.603755 | AE35: 1.568e-08
A36: 3 | B36: 0.0903 | C36: 197201600 | D36: 926 | E36: 212.96067 | F36: 246.40833 | G36: 1.236699 | I36: 3 | J36: 0.0903 | K36: 28887.763 | L36: 970 | M36: 29.781199 | N36: 18.370908 | O36: 2.37596e-07 | Q36: 3 | R36: 0.0903 | S36: 60353.348 | T36: 996 | U36: 60.595731 | V36: 104.94421 | W36: 4.528924 | Y36: 3 | Z36: 0.0903 | AA36: 50316.241 | AB36: 949 | AC36: 53.020275 | AD36: 108.08763 | AE36: 6.71359e-07
A37: 4 | B37: 0.0767 | C37: 796218600 | D37: 787 | E37: 1011.7135 | F37: 393.91319 | G37: 4.993281 | I37: 4 | J37: 0.0767 | K37: 553639.62 | L37: 771 | M37: 718.07993 | N37: 1658.8355 | O37: 4.55357 | Q37: 4 | R37: 0.0767 | S37: 13368.735 | T37: 817 | U37: 16.363201 | V37: 33.475006 | W37: 1.003192 | Y37: 4 | Z37: 0.0767 | AA37: 2106806.3 | AB37: 760 | AC37: 2772.1135 | AD37: 1049.7539 | AE37: 28.110673
A38: 5 | B38: 0.0142 | C38: 5186 | D38: 151 | E38: 3.4344e-08 | F38: 1.355e-08 | G38: 3.3e-11 | I38: 5 | J38: 0.0142 | K38: 3.993 | L38: 130 | M38: 3.0715e-08 | N38: 1.1865e-08 | O38: 3.3e-11 | Q38: 5 | R38: 0.0142 | S38: 2.687 | T38: 132 | U38: 2.0356e-08 | V38: 9.26e-09 | W38: 2.02e-10 | Y38: 5 | Z38: 0.0142 | AA38: 2.278 | AB38: 144 | AC38: 1.5819e-08 | AD38: 7.547e-09 | AE38: 3e-11
A39: 6 | B39: 0.3801 | C39: 540205 | D39: 3918 | E39: 1.37878e-07 | F39: 1.11407e-07 | G39: 3.388e-09 | I39: 6 | J39: 0.3801 | K39: 587.443 | L39: 3979 | M39: 1.47636e-07 | N39: 9.7044e-08 | O39: 4.832e-09 | Q39: 6 | R39: 0.3801 | S39: 720.684 | T39: 4003 | U39: 1.80036e-07 | V39: 1.00523e-07 | W39: 5.408e-08 | Y39: 6 | Z39: 0.3801 | AA39: 658.687 | AB39: 3993 | AC39: 1.6496e-07 | AD39: 7.8259e-08 | AE39: 8.789e-09
A40: 7 | B40: 0.0453 | C40: 11277410000 | D40: 462 | E40: 24409.972 | F40: 14434.16 | G40: 70.723371 | I40: 7 | J40: 0.0453 | K40: 8709268.2 | L40: 504 | M40: 17280.294 | N40: 6253.0849 | O40: 71.631908 | Q40: 7 | R40: 0.0453 | S40: 588599.81 | T40: 495 | U40: 1189.0905 | V40: 1875.6621 | W40: 44.168613 | Y40: 7 | Z40: 0.0453 | AA40: 3705459.4 | AB40: 493 | AC40: 7516.1448 | AD40: 11780.573 | AE40: 49.441165
A41: 8 | B41: 0.082 | C41: 165230 | D41: 903 | E41: 1.82979e-07 | F41: 1.6026e-07 | G41: 1.036e-09 | I41: 8 | J41: 0.082 | K41: 117.524 | L41: 862 | M41: 1.36339e-07 | N41: 9.9482e-08 | O41: 9.67e-10 | Q41: 8 | R41: 0.082 | S41: 145.034 | T41: 800 | U41: 1.81292e-07 | V41: 1.45552e-07 | W41: 1.0883e-08 | Y41: 8 | Z41: 0.082 | AA41: 49.348 | AB41: 838 | AC41: 5.8888e-08 | AD41: 2.7918e-08 | AE41: 6.58e-10
A42: 9 | B42: 0.0061 | C42: 577427900 | D42: 71 | E42: 8132.788 | F42: 2271.5446 | G42: 3.621192 | I42: 9 | J42: 0.0061 | K42: 529017.52 | L42: 60 | M42: 8816.9587 | N42: 2499.2521 | O42: 4.351058 | Q42: 9 | R42: 0.0061 | S42: 15148.761 | T42: 65 | U42: 233.05786 | V42: 658.22433 | W42: 1.136765 | Y42: 9 | Z42: 0.0061 | AA42: 293722.58 | AB42: 54 | AC42: 5439.307 | AD42: 6223.717 | AE42: 3.919079
A43: 10 | B43: 0.0055 | C43: 362968500 | D43: 47 | E43: 7722.735 | F43: 2258.0367 | G43: 2.276264 | I43: 10 | J43: 0.0055 | K43: 476992.22 | L43: 51 | M43: 9352.7887 | N43: 2686.4513 | O43: 3.923161 | Q43: 10 | R43: 0.0055 | S43: 14283.399 | T43: 51 | U43: 280.06665 | V43: 814.08557 | W43: 1.071828 | Y43: 10 | Z43: 0.0055 | AA43: 200860.42 | AB43: 60 | AC43: 3347.6737 | AD43: 4345.6788 | AE43: 2.680038
...

Sheet Mig 5x
A1: W | C1: Query volume | D1: Original query volume
A2: alpha | C2: 10000 | D2: 50333
A3: beta | C3: 10000 | D3: 1489126
A4: gamma | C4: 10000 | D4: 3623390
A6: W beta (2013) | B6: Avg q time | C6: Total time (sec) on query volume | D6: Total time (sec) on original query volume | F6: Total time (min) on query volume | G6: Total time (min) on original query volume | K6: Mig time (sec) from D1_alpha | L6: Scaled (sec) | M6: Scaled (min) | N6: Scaled (h) | O6: Scaled (d)
A7: D2_alpha | B7: ='Query 5x'!E30 -> 62.661454 | C7: =$B7*C$3/1000 -> 626.61454 | D7: =$B7*D$3/1000 -> 93310.801 | F7: =C7/60 -> 10.443576 | G7: =D7/60 -> 1555.18
A8: D2_beta | B8: ='Query 5x'!M30 -> 1.9067935 | C8: =$B8*C$3/1000 -> 19.067935 | D8: =$B8*D$3/1000 -> 2839.4558 | F8: =C8/60 -> 0.31779892 | G8: =D8/60 -> 47.324264 | K8: 319.2 | L8: =K8*$D$24 -> 785870.4 | M8: =L8/60 -> 13097.84 | N8: =M8/60 -> 218.29733 | O8: =N8/24 -> 9.0957222
A10: W gamma (2023) | B10: Avg q time | C10: Total time (sec) on query volume | D10: Total time (sec) on original query volume | F10: Total time (min) on query volume | G10: Total time (min) on original query volume | H10: Total time (h) on original query volume | I10: Total time (d) on original query volume | K10: Mig time (sec) from D2_beta | L10: Scaled (sec) | M10: Scaled (min) | N10: Scaled (h) | O10: Scaled (d)
A11: D3_alpha | B11: ='Query 5x'!E49 -> 1546.356 | C11: =$B11*C$4/1000 -> 15463.56 | D11: =$B11*D$4/1000 -> 5603050.8 | F11: =C11/60 -> 257.726 | G11: =D11/60 -> 93384.181 | H11: =G11/60 -> 1556.403 | I11: =H11/24 -> 64.850126
A12: D3_beta | B12: ='Query 5x'!M49 -> 1134.6376 | C12: =$B12*C$4/1000 -> 11346.376 | D12: =$B12*D$4/1000 -> 4111234.5 | F12: =C12/60 -> 189.10627 | G12: =D12/60 -> 68520.576 | H12: =G12/60 -> 1142.0096 | I12: =H12/24 -> 47.583733
A13: D3_gamma | B13: ='Query 5x'!U49 -> 125.52677 | C13: =$B13*C$4/1000 -> 1255.2677 | D13: =$B13*D$4/1000 -> 454832.46 | F13: =C13/60 -> 20.921129 | G13: =D13/60 -> 7580.5409 | H13: =G13/60 -> 126.34235 | I13: =H13/24 -> 5.2642645 | K13: 521.9 | L13: =K13*$D$24 -> 1284917.8 | M13: =L13/60 -> 21415.297 | N13: =M13/60 -> 356.92161 | O13: =N13/24 -> 14.871734
A23: Table | B23: Original card | C23: Sample card | D23: Rate
A24: PhotoObjAll | B24: 1231000000 | C24: 500000 | D24: =B24/C24 -> 2462

Sheet Query 10x
A1: 2003 | B1: Weight | C1: Total_Execution_Time | D1: Execution_Count | E1: Mean_Execution_Time | F1: Std_Dev_Execution_Time | G1: Total_Execution_Percentage | H1: Actual_Rows
A2: QueryType
A3: 1 | B3: 0.603 | C3: 11484.314 | D3: 6013 | E3: 1.909914 | F3: 1.215342 | G3: 1.466908 | H3: 1
A4: 2 | B4: 0.2246 | C4: 404097.15 | D4: 2211 | E4: 182.76669 | F4: 101.39147 | G4: 51.615912 | H4: 941.1
A5: 3 | B5: 0.0475 | C5: 111099.35 | D5: 512 | E5: 216.99092 | F5: 154.42049 | G5: 14.19088 | H5: 293.5
A6: 4 | B6: 0.114 | C6: 256011.49 | D6: 1151 | E6: 222.42527 | F6: 156.76627 | G6: 32.700717 | H6: 303.6
A7: 5 | B7: 0.0109 | C7: 200.287 | D7: 113 | E7: 1.772451 | F7: 9.586843 | G7: 2.5583e-08 | H7: 1
E8: =SUMPRODUCT(B3:B7,E3:E7) -> 77.883946 | H8: =SUMPRODUCT(B3:B7,H3:H7) -> 260.53661
A10: 2003 opt | B10: Weight | C10: Total_Execution_Time | D10: Execution_Count | E10: Mean_Execution_Time | F10: Std_Dev_Execution_Time | G10: Total_Execution_Percentage | H10: Actual_Rows
A11: QueryType
A12: 1 | B12: 0.603 | C12: 4761.021 | D12: 6104 | E12: 7.79984e-07 | F12: 6.69025e-07 | G12: 8.312397 | H12: 1
A13: 2 | B13: 0.2246 | C13: 18215.064 | D13: 2224 | E13: 8.190227 | F13: 5.511903 | G13: 31.802181 | H13: 942.4
A14: 3 | B14: 0.0475 | C14: 9833.461 | D14: 472 | E14: 20.833604 | F14: 22.772856 | G14: 17.16851 | H14: 293.7
A15: 4 | B15: 0.114 | C15: 24293.846 | D15: 1095 | E15: 22.186161 | F15: 20.771302 | G15: 42.415293 | H15: 270.2
A16: 5 | B16: 0.0109 | C16: 172.756 | D16: 105 | E16: 1.645295 | F16: 5.028456 | G16: 3.01619e-07 | H16: 1
E17: =SUMPRODUCT(B12:B16,E12:E16) -> 5.3762777 | F17: =SQRT(SUMPRODUCT(B12:B16,F12:F16)/SUM(B12:B16)) -> 2.1777105 | H17: =SUMPRODUCT(B12:B16,H12:H16) -> 257.03049
A19: 2013 over03opt | B19: Weight | C19: Total_Execution_Time | D19: Execution_Count | E19: Mean_Execution_Time | F19: Std_Dev_Execution_Time | G19: Total_Execution_Percentage | H19: Actual_Rows | J19: 2013 opt | K19: Weight | L19: Total_Execution_Time | M19: Execution_Count | N19: Mean_Execution_Time | O19: Std_Dev_Execution_Time | P19: Total_Execution_Percentage | Q19: Actual_Rows | S19: 2013 | T19: Weight | U19: Total_Execution_Time | V19: Execution_Count | W19: Mean_Execution_Time | X19: Std_Dev_Execution_Time | Y19: Total_Execution_Percentage | Z19: Actual_Rows
A20: QueryType | J20: QueryType | S20: QueryType
A21: 1 | B21: 0.1066 | C21: 1001.536 | D21: 1878 | E21: 5.33299e-07 | F21: 5.25048e-07 | G21: 8.6368e-08 | H21: 1 | J21: 1 | K21: 0.1066 | L21: 1476.603 | M21: 1866 | N21: 7.9132e-07 | O21: 4.50067e-07 | P21: 3.866469 | Q21: 1 | S21: 1 | T21: 0.1066 | U21: 3612.37 | V21: 1870 | W21: 1.931749 | X21: 1.315606 | Y21: 7.0324e-07 | Z21: 1
A22: 2 | B22: 0.0133 | C22: 1756.271 | D22: 235 | E22: 7.473494 | F22: 5.262465 | G22: 1.51453e-07 | H22: 1007 | J22: 2 | K22: 0.0133 | L22: 4379.531 | M22: 253 | N22: 17.310399 | O22: 12.164324 | P22: 11.467754 | Q22: 559.2 | S22: 2 | T22: 0.0133 | U22: 80758.187 | V22: 250 | W22: 323.03275 | X22: 169.00903 | Y22: 15.721648 | Z22: 966.7
A23: 3 | B23: 0.1413 | C23: 1151521.7 | D23: 2570 | E23: 448.06294 | F23: 252.06518 | G23: 99.302346 | H23: 418.3 | J23: 3 | K23: 0.1413 | L23: 21221.744 | M23: 2493 | N23: 8.512533 | O23: 9.766202 | P23: 55.568904 | Q23: 426.3 | S23: 3 | T23: 0.1413 | U23: 429210.47 | V23: 2600 | W23: 165.08095 | X23: 95.267079 | Y23: 83.556804 | Z23: 415.9
A24: 4 | B24: 0.0547 | C24: 1163.91 | D24: 989 | E24: 1.176855 | F24: 21.235512 | G24: 1.00371e-07 | H24: 1 | J24: 4 | K24: 0.0547 | L24: 1108.655 | M24: 968 | N24: 1.145305 | O24: 4.355959 | P24: 2.903001 | Q24: 1 | S24: 4 | T24: 0.0547 | U24: 19.973 | V24: 929 | W24: 2.1499e-08 | X24: 9.178e-09 | Y24: 3.888e-09 | Z24: 1
A25: 5 | B25: 0.0468 | C25: 21.918 | D25: 839 | E25: 2.6124e-08 | F25: 1.3718e-08 | G25: 1.89e-09 | H25: 0.16 | J25: 5 | K25: 0.0468 | L25: 1655.743 | M25: 817 | N25: 2.026613 | O25: 6.565184 | P25: 4.335545 | Q25: 0.17 | S25: 5 | T25: 0.0468 | U25: 10.08 | V25: 857 | W25: 1.1762e-08 | X25: 6.278e-09 | Y25: 1.962e-09 | Z25: 0.16
A26: 6 | B26: 0.1078 | C26: 4046.949 | D26: 1939 | E26: 2.087132 | F26: 19.679151 | G26: 3.48992e-07 | H26: 1 | J26: 6 | K26: 0.1078 | L26: 6825.679 | M26: 1976 | N26: 3.454291 | O26: 7.93215 | P26: 17.872966 | Q26: 1 | S26: 6 | T26: 0.1078 | U26: 32.515 | V26: 1940 | W26: 1.676e-08 | X26: 6.759e-09 | Y26: 6.33e-09 | Z26: 1
A27: 7 | B27: 0.0349 | C27: 14.456 | D27: 661 | E27: 2.187e-08 | F27: 1.1472e-08 | G27: 1.247e-09 | H27: 4 | J27: 7 | K27: 0.0349 | L27: 700.51 | M27: 654 | N27: 1.071116 | O27: 3.40176 | P27: 1.834278 | Q27: 4 | S27: 7 | T27: 0.0349 | U27: 12.382 | V27: 629 | W27: 1.9685e-08 | X27: 6.802e-09 | Y27: 2.41e-09 | Z27: 4
A28: 8 | B28: 0.0263 | C28: 9.464 | D28: 468 | E28: 2.0222e-08 | F28: 9.91e-09 | G28: 8.16e-10 | H28: 1 | J28: 8 | K28: 0.0263 | L28: 18.889 | M28: 458 | N28: 4.1242e-08 | O28: 7.2326e-08 | P28: 4.9461e-08 | Q28: 1 | S28: 8 | T28: 0.0263 | U28: 8.615 | V28: 440 | W28: 1.958e-08 | X28: 7.152e-09 | Y28: 1.677e-09 | Z28: 1
A29: 9 | B29: 0.0273 | C29: 75.572 | D29: 421 | E29: 1.79506e-07 | F29: 8.78224e-07 | G29: 6.517e-09 | H29: 0.13 | J29: 9 | K29: 0.0273 | L29: 802.609 | M29: 515 | N29: 1.558464 | O29: 4.569583 | P29: 2.101623 | Q29: 0.08 | S29: 9 | T29: 0.0273 | U29: 10.473 | V29: 485 | W29: 2.1594e-08 | X29: 9.682e-09 | Y29: 2.039e-09 | Z29: 0.88
E30: =SUMPRODUCT(B21:B29,E21:E29) -> 63.700057 | H30: =SUMPRODUCT(B21:B29,H21:H29) -> 72.944927 | N30: =SUMPRODUCT(K21:K29,N21:N29) -> 2.0428436 | O30: =SQRT(SUMPRODUCT(K21:K29,O21:O29)/SUM(K21:K29)) -> 2.3872905 | Q30: =SUMPRODUCT(K21:K29,Q21:Q29) -> 68.11869 | W30: =SUMPRODUCT(T21:T29,W21:W29) -> 27.828198 | Z30: =SUMPRODUCT(T21:T29,Z21:Z29) -> 72.090292
A32: 2023 over03opt | B32: Weight | C32: Total_Execution_Time | D32: Execution_Count | E32: Mean_Execution_Time | F32: Std_Dev_Execution_Time | G32: Total_Execution_Percentage | H32: Actual_Rows | J32: 2023 over13opt | K32: Weight | L32: Total_Execution_Time | M32: Execution_Count | N32: Mean_Execution_Time | O32: Std_Dev_Execution_Time | P32: Total_Execution_Percentage | Q32: Actual_Rows | S32: 2023 opt | T32: Weight | U32: Total_Execution_Time | V32: Execution_Count | W32: Mean_Execution_Time | X32: Std_Dev_Execution_Time | Y32: Total_Execution_Percentage | Z32: Actual_Rows | AB32: 2023 | AC32: Weight | AD32: Total_Execution_Time | AE32: Execution_Count | AF32: Mean_Execution_Time | AG32: Std_Dev_Execution_Time | AH32: Total_Execution_Percentage | AI32: Actual_Rows
A33: QueryType | J33: QueryType | S33: QueryType | AB33: QueryType
A34: 1 | B34: 0.0793 | C34: 6573421 | D34: 837 | E34: 7.85355 | F34: 5.469596 | G34: 2.0287e-08 | H34: 937 | J34: 1 | K34: 0.0793 | L34: 1184821000 | M34: 848 | N34: 1397.1948 | O34: 619.54401 | P34: 5.025472 | Q34: 953.2 | S34: 1 | T34: 0.0793 | U34: 15231.263 | V34: 875 | W34: 17.407158 | X34: 9.247704 | Y34: 5.9184e-07 | Z34: 965.3 | AB34: 1 | AC34: 0.0793 | AD34: 277586.9 | AE34: 879 | AF34: 315.79852 | AG34: 178.20421 | AH34: 2.340834 | AI34: 952.6
A35: 2 | B35: 0.0616 | C35: 338687 | D35: 663 | E35: 5.1084e-07 | F35: 4.9877e-07 | G35: 1.045e-09 | H35: 1 | J35: 2 | K35: 0.0616 | L35: 347296 | M35: 637 | N35: 5.45206e-07 | O35: 3.78008e-07 | P35: 1.473e-09 | Q35: 1 | S35: 2 | T35: 0.0616 | U35: 463.615 | V35: 631 | W35: 7.34731e-07 | X35: 4.83002e-07 | Y35: 1.8015e-08 | Z35: 1 | AB35: 2 | AC35: 0.0616 | AD35: 1268.348 | AE35: 639 | AF35: 1.984895 | AG35: 1.41603 | AH35: 1.0696e-08 | AI35: 1
A36: 3 | B36: 0.0903 | C36: 271599100 | D36: 955 | E36: 284.39692 | F36: 274.91044 | G36: 8.38216e-07 | H36: 154.7 | J36: 3 | K36: 0.0903 | L36: 33637900 | M36: 946 | N36: 35.55803 | O36: 11.123042 | P36: 1.42677e-07 | Q36: 2.5 | S36: 3 | T36: 0.0903 | U36: 45109.779 | V36: 1003 | W36: 44.974854 | X36: 112.10973 | Y36: 1.752827 | Z36: 2.45 | AB36: 3 | AC36: 0.0903 | AD36: 58990.331 | AE36: 975 | AF36: 60.502904 | AG36: 109.5541 | AH36: 4.97454e-07 | AI36: 142.2
A37: 4 | B37: 0.0767 | C37: 1645561000 | D37: 832 | E37: 1977.8373 | F37: 790.46935 | G37: 5.07857 | H37: 3746.4 | J37: 4 | K37: 0.0767 | L37: 954682000 | M37: 796 | N37: 1199.3493 | O37: 3010.981 | P37: 4.049326 | Q37: 3842.7 | S37: 4 | T37: 0.0767 | U37: 27032.904 | V37: 742 | W37: 36.432485 | X37: 66.570027 | Y37: 1.050416 | Z37: 3283 | AB37: 4 | AC37: 0.0767 | AD37: 2123145.8 | AE37: 753 | AF37: 2819.5827 | AG37: 1034.788 | AH37: 17.90406 | AI37: 29545.8
A38: 5 | B38: 0.0142 | C38: 7123 | D38: 156 | E38: 4.566e-08 | F38: 2.1108e-08 | G38: 2.2e-11 | H38: 0.17 | J38: 5 | K38: 0.0142 | L38: 6304 | M38: 169 | N38: 3.7302e-08 | O38: 1.9744e-08 | P38: 2.7e-11 | Q38: 0.18 | S38: 5 | T38: 0.0142 | U38: 3.635 | V38: 135 | W38: 2.6926e-08 | X38: 1.8674e-08 | Y38: 1.41e-10 | Z38: 0 | AB38: 5 | AC38: 0.0142 | AD38: 2.61 | AE38: 153 | AF38: 1.7059e-08 | AG38: 6.126e-09 | AH38: 2.2e-11 | AI38: 0.19
A39: 6 | B39: 0.3801 | C39: 599991 | D39: 4017 | E39: 1.49363e-07 | F39: 1.31662e-07 | G39: 1.852e-09 | H39: 1 | J39: 6 | K39: 0.3801 | L39: 648072 | M39: 3966 | N39: 1.63407e-07 | O39: 1.27697e-07 | P39: 2.749e-09 | Q39: 1 | S39: 6 | T39: 0.3801 | U39: 10646.595 | V39: 3915 | W39: 2.719437 | X39: 31.600627 | Y39: 4.13694e-07 | Z39: 1 | AB39: 6 | AC39: 0.3801 | AD39: 635.85 | AE39: 3955 | AF39: 1.60771e-07 | AG39: 6.7832e-08 | AH39: 5.362e-09 | AI39: 1
A40: 7 | B40: 0.0453 | C40: 24098270000 | D40: 455 | E40: 52963.233 | F40: 26501.069 | G40: 74.372681 | H40: 8715.8 | J40: 7 | K40: 0.0453 | L40: 15910070000 | M40: 463 | N40: 34362.993 | O40: 12719.432 | P40: 67.483248 | Q40: 9241 | S40: 7 | T40: 0.0453 | U40: 1140641.3 | V40: 475 | W40: 2401.3502 | X40: 4730.6748 | Y40: 44.321816 | Z40: 9669 | AB40: 7 | AC40: 0.0453 | AD40: 6775651.5 | AE40: 493 | AF40: 13743.715 | AG40: 20858.459 | AH40: 57.137703 | AI40: 90618.3
A41: 8 | B41: 0.082 | C41: 492534 | D41: 831 | E41: 5.927e-07 | F41: 10.765121 | G41: 1.52e-09 | H41: 0.64 | J41: 8 | K41: 0.082 | L41: 176051 | M41: 837 | N41: 2.10336e-07 | O41: 1.720721 | P41: 7.47e-10 | Q41: 0.64 | S41: 8 | T41: 0.082 | U41: 1474.13 | V41: 890 | W41: 1.656326 | X41: 12.748148 | Y41: 5.728e-08 | Z41: 0.64 | AB41: 8 | AC41: 0.082 | AD41: 47.105 | AE41: 796 | AF41: 5.9177e-08 | AG41: 2.915e-08 | AH41: 3.97e-10 | AI41: 0.62
A42: 9 | B42: 0.0061 | C42: 1006566000 | D42: 69 | E42: 14587.918 | F42: 5341.1772 | G42: 3.10649 | H42: 3940.9 | J42: 9 | K42: 0.0061 | L42: 1192275000 | M42: 65 | N42: 18342.694 | O42: 6229.0344 | P42: 5.057088 | Q42: 3552 | S42: 9 | T42: 0.0061 | U42: 41258.958 | V42: 60 | W42: 687.6493 | X42: 2011.0977 | Y42: 1.603196 | Z42: 3577.6 | AB42: 9 | AC42: 0.0061 | AD42: 470177.05 | AE42: 66 | AF42: 7123.8947 | AG42: 11264.877 | AH42: 3.964908 | AI42: 28297.1
A43: 10 | B43: 0.0055 | C43: 598720400 | D43: 44 | E43: 13607.281 | F43: 3922.4007 | G43: 1.847786 | H43: 3954.1 | J43: 10 | K43: 0.0055 | L43: 946237600 | M43: 49 | N43: 19310.971 | O43: 4612.5947 | P43: 4.013509 | Q43: 2027.2 | S43: 10 | T43: 0.0055 | U43: 28966.191 | V43: 59 | W43: 490.95239 | X43: 1407.0352 | Y43: 1.125537 | Z43: 4338.8 | AB43: 10 | AC43: 0.0055 | AD43: 409231.83 | AE43: 57 | AF43: 7179.5058 | AG43: 11650.16 | AH43: 3.45097 | AI43: 3762.5
...

Sheet Mig 10x
A1: W | C1: Query volume | D1: Original query volume
A2: alpha | C2: 10000 | D2: 50333
A3: beta | C3: 10000 | D3: 1489126
A4: gamma | C4: 10000 | D4: 3623390
A6: W beta (2013) | B6: Avg q time | C6: Total time (sec) on query volume | D6: Total time (sec) on original query volume | F6: Total time (min) on query volume | G6: Total time (min) on original query volume | K6: Mig time (sec) from D1_alpha | L6: Scaled (sec) | M6: Scaled (min) | N6: Scaled (h) | O6: Scaled (d)
A7: D2_alpha | B7: ='Query 10x'!E30 -> 63.700057 | C7: =$B7*C$3/1000 -> 637.00057 | D7: =$B7*D$3/1000 -> 94857.412 | F7: =C7/60 -> 10.616676 | G7: =D7/60 -> 1580.9569
A8: D2_beta | B8: ='Query 10x'!N30 -> 2.0428436 | C8: =$B8*C$3/1000 -> 20.428436 | D8: =$B8*D$3/1000 -> 3042.0515 | F8: =C8/60 -> 0.34047393 | G8: =D8/60 -> 50.700858 | K8: 675 | L8: =K8*$D$24 -> 830925 | M8: =L8/60 -> 13848.75 | N8: =M8/60 -> 230.8125 | O8: =N8/24 -> 9.6171875
K9: 415
A10: W gamma (2023) | B10: Avg q time | C10: Total time (sec) on query volume | D10: Total time (sec) on original query volume | F10: Total time (min) on query volume | G10: Total time (min) on original query volume | H10: Total time (h) on original query volume | I10: Total time (d) on original query volume | K10: Mig time (sec) from D2_beta | L10: Scaled (sec) | M10: Scaled (min) | N10: Scaled (h) | O10: Scaled (d)
A11: D3_alpha | B11: ='Query 10x'!E49 -> 3249.2021 | C11: =$B11*C$4/1000 -> 32492.021 | D11: =$B11*D$4/1000 -> 11773127 | F11: =C11/60 -> 541.53369 | G11: =D11/60 -> 196218.78 | H11: =G11/60 -> 3270.3129 | I11: =H11/24 -> 136.26304
A12: D3_beta | B12: ='Query 10x'!N49 -> 2304.2816 | C12: =$B12*C$4/1000 -> 23042.816 | D12: =$B12*D$4/1000 -> 8349311 | F12: =C12/60 -> 384.04694 | G12: =D12/60 -> 139155.18 | H12: =G12/60 -> 2319.2531 | I12: =H12/24 -> 96.635544
A13: D3_gamma | B13: ='Query 10x'!W49 -> 240.55844 | C13: =$B13*C$4/1000 -> 2405.5844 | D13: =$B13*D$4/1000 -> 871637.03 | F13: =C13/60 -> 40.093073 | G13: =D13/60 -> 14527.284 | H13: =G13/60 -> 242.1214 | I13: =H13/24 -> 10.088392 | K13: 922 | L13: =K13*$D$24 -> 1134982 | M13: =L13/60 -> 18916.367 | N13: =M13/60 -> 315.27278 | O13: =N13/24 -> 13.136366
K14: 623
K18: 1144830
K19: 1435961
K20: 1284917
K21: 1134982
A23: Table | B23: Original card | C23: Sample card | D23: Rate
A24: PhotoObjAll | B24: 1231000000 | C24: 1000000 | D24: =B24/C24 -> 1231

Sheet Storage
B1: Total size (bytes) | L1: Schema | M1: Table | N1: Total | O1: Total H | P1: Data | Q1: Indexes | R1: Scale | S1: $D_1$ | T1: $D_1^{\alpha}$ | U1: $D_2$ | V1: $D_2^{\alpha}$ | W1: $D_2^{\beta}$ | X1: $D_3$ | Y1: $D_3^{\alpha}$ | Z1: $D_3^{\beta}$ | AA1: $D_3^{\gamma}$ | AB1: $D_1$ | AC1: $D_1^{\alpha}$ | AD1: $D_2$ | AE1: $D_2^{\alpha}$ | AF1: $D_2^{\beta}$ | AG1: $D_3$ | AH1: $D_3^{\alpha}$ | AI1: $D_3^{\beta}$ | AJ1: $D_3^{\gamma}$
A2: Scale | B2: $D_1$ | C2: $D_1^{\alpha}$ | D2: $D_2$ | E2: $D_2^{\alpha}$ | F2: $D_2^{\beta}$ | G2: $D_3$ | H2: $D_3^{\alpha}$ | I2: $D_3^{\beta}$ | J2: $D_3^{\gamma}$ | L2: aa_sdss2003 | M2: photoobjall | N2: 625467392 | O2: 596 MB | P2: 5888 kB | Q2: 5312 kB | R2: =IF(ISNUMBER(SEARCH("_2x", L2)), "2x", IF(ISNUMBER(SEARCH("_5x", L2)), "5x", IF(ISNUMBER(SEARCH("_10x", L2)), "10x", "1x"))) -> 1x | S2: 1 | AB2: =IF(S2=1,$N2,"") -> 625467392 | AC2: =IF(T2=1,$N2,"") | AE2: =IF(V2=1,$N2,"") | AF2: =IF(W2=1,$N2,"") | AH2: =IF(Y2=1,$N2,"") | AI2: =IF(Z2=1,$N2,"") | AJ2: =IF(AA2=1,$N2,"")
A3: 1x | B3: =SUMIF($R$2:$AJ$329,$A3,AB$2:AB$329) -> 715800576 | C3: =SUMIF($R$2:$AJ$329,$A3,AC$2:AC$329) -> 738615296 | D3: =SUMIF($R$2:$AJ$329,$A3,AD$2:AD$329) -> 890109952 | E3: =SUMIF($R$2:$AJ$329,$A3,AE$2:AE$329) -> 917856256 | F3: =SUMIF($R$2:$AJ$329,$A3,AF$2:AF$329) -> 893943808 | G3: =SUMIF($R$2:$AJ$329,$A3,AG$2:AG$329) -> 928399360 | H3: =SUMIF($R$2:$AJ$329,$A3,AH$2:AH$329) -> 934887424 | I3: =SUMIF($R$2:$AJ$329,$A3,AI$2:AI$329) -> 925286400 | J3: =SUMIF($R$2:$AJ$329,$A3,AJ$2:AJ$329) -> 920936448 | L3: aa_sdss2003 | M3: photoz | N3: 18178048 | O3: 17 MB | P3: 17 MB | Q3: 784 kB | R3: =IF(ISNUMBER(SEARCH("_2x", L3)), "2x", IF(ISNUMBER(SEARCH("_5x", L3)), "5x", IF(ISNUMBER(SEARCH("_10x", L3)), "10x", "1x"))) -> 1x | S3: 1 | T3: 1 | AB3: =IF(S3=1,$N3,"") -> 18178048 | AC3: =IF(T3=1,$N3,"") -> 18178048 | AE3: =IF(V3=1,$N3,"") | AF3: =IF(W3=1,$N3,"") | AH3: =IF(Y3=1,$N3,"") | AI3: =IF(Z3=1,$N3,"") | AJ3: =IF(AA3=1,$N3,"")
A4: 2x | B4: =SUMIF($R$2:$AJ$329,$A4,AB$2:AB$329) -> 1431248896 | C4: =SUMIF($R$2:$AJ$329,$A4,AC$2:AC$329) -> 1476624384 | D4: =SUMIF($R$2:$AJ$329,$A4,AD$2:AD$329) -> 1677426688 | E4: =SUMIF($R$2:$AJ$329,$A4,AE$2:AE$329) -> 1732567040 | F4: =SUMIF($R$2:$AJ$329,$A4,AF$2:AF$329) -> 1684660224 | G4: =SUMIF($R$2:$AJ$329,$A4,AG$2:AG$329) -> 1753694208 | H4: =SUMIF($R$2:$AJ$329,$A4,AH$2:AH$329) -> 1766490112 | I4: =SUMIF($R$2:$AJ$329,$A4,AI$2:AI$329) -> 1747132416 | J4: =SUMIF($R$2:$AJ$329,$A4,AJ$2:AJ$329) -> 1746059264 | L4: aa_sdss2003 | M4: specobjall | N4: 72155136 | O4: 69 MB | P4: 1488 kB | Q4: 1856 kB | R4: =IF(ISNUMBER(SEARCH("_2x", L4)), "2x", IF(ISNUMBER(SEARCH("_5x", L4)), "5x", IF(ISNUMBER(SEARCH("_10x", L4)), "10x", "1x"))) -> 1x | S4: 1 | AB4: =IF(S4=1,$N4,"") -> 72155136 | AC4: =IF(T4=1,$N4,"") | AE4: =IF(V4=1,$N4,"") | AF4: =IF(W4=1,$N4,"") | AH4: =IF(Y4=1,$N4,"") | AI4: =IF(Z4=1,$N4,"") | AJ4: =IF(AA4=1,$N4,"")
A5: 5x | B5: =SUMIF($R$2:$AJ$329,$A5,AB$2:AB$329) -> 3577634816 | C5: =SUMIF($R$2:$AJ$329,$A5,AC$2:AC$329) -> 3690553344 | D5: =SUMIF($R$2:$AJ$329,$A5,AD$2:AD$329) -> 4039483392 | E5: =SUMIF($R$2:$AJ$329,$A5,AE$2:AE$329) -> 4176658432 | F5: =SUMIF($R$2:$AJ$329,$A5,AF$2:AF$329) -> 4056940544 | G5: =SUMIF($R$2:$AJ$329,$A5,AG$2:AG$329) -> 4231340032 | H5: =SUMIF($R$2:$AJ$329,$A5,AH$2:AH$329) -> 4262830080 | I5: =SUMIF($R$2:$AJ$329,$A5,AI$2:AI$329) -> 4214415360 | J5: =SUMIF($R$2:$AJ$329,$A5,AJ$2:AJ$329) -> 4223451136 | L5: aa_sdss2003_optimized | M5: field | N5: 70385664 | O5: 67 MB | P5: 664 kB | Q5: 264 kB | R5: =IF(ISNUMBER(SEARCH("_2x", L5)), "2x", IF(ISNUMBER(SEARCH("_5x", L5)), "5x", IF(ISNUMBER(SEARCH("_10x", L5)), "10x", "1x"))) -> 1x | V5: 1 | Y5: 1 | AB5: =IF(S5=1,$N5,"") | AC5: =IF(T5=1,$N5,"") | AE5: =IF(V5=1,$N5,"") -> 70385664 | AF5: =IF(W5=1,$N5,"") | AH5: =IF(Y5=1,$N5,"") -> 70385664 | AI5: =IF(Z5=1,$N5,"") | AJ5: =IF(AA5=1,$N5,"")
A6: 10x | B6: =SUMIF($R$2:$AJ$329,$A6,AB$2:AB$329) -> 7154958336 | C6: =SUMIF($R$2:$AJ$329,$A6,AC$2:AC$329) -> 7380467712 | D6: =SUMIF($R$2:$AJ$329,$A6,AD$2:AD$329) -> 7976255488 | E6: =SUMIF($R$2:$AJ$329,$A6,AE$2:AE$329) -> 8250155008 | F6: =SUMIF($R$2:$AJ$329,$A6,AF$2:AF$329) -> 8010678272 | G6: =SUMIF($R$2:$AJ$329,$A6,AG$2:AG$329) -> 8360648704 | H6: =SUMIF($R$2:$AJ$329,$A6,AH$2:AH$329) -> 8423366656 | I6: =SUMIF($R$2:$AJ$329,$A6,AI$2:AI$329) -> 8326438912 | J6: =SUMIF($R$2:$AJ$329,$A6,AJ$2:AJ$329) -> 8351916032 | L6: aa_sdss2003_optimized | M6: frame | N6: 31948800 | O6: 30 MB | P6: 29 MB | Q6: 1392 kB | R6: =IF(ISNUMBER(SEARCH("_2x", L6)), "2x", IF(ISNUMBER(SEARCH("_5x", L6)), "5x", IF(ISNUMBER(SEARCH("_10x", L6)), "10x", "1x"))) -> 1x | V6: 1 | Y6: 1 | AB6: =IF(S6=1,$N6,"") | AC6: =IF(T6=1,$N6,"") | AE6: =IF(V6=1,$N6,"") -> 31948800 | AF6: =IF(W6=1,$N6,"") | AH6: =IF(Y6=1,$N6,"") -> 31948800 | AI6: =IF(Z6=1,$N6,"") | AJ6: =IF(AA6=1,$N6,"")
L7: aa_sdss2003_optimized | M7: galspecextra | N7: 30597120 | O7: 29 MB | P7: 29 MB | Q7: 496 kB | R7: =IF(ISNUMBER(SEARCH("_2x", L7)), "2x", IF(ISNUMBER(SEARCH("_5x", L7)), "5x", IF(ISNUMBER(SEARCH("_10x", L7)), "10x", "1x"))) -> 1x | Y7: 1 | AB7: =IF(S7=1,$N7,"") | AC7: =IF(T7=1,$N7,"") | AE7: =IF(V7=1,$N7,"") | AF7: =IF(W7=1,$N7,"") | AH7: =IF(Y7=1,$N7,"") -> 30597120 | AI7: =IF(Z7=1,$N7,"") | AJ7: =IF(AA7=1,$N7,"")
B8: Total size (MB) | L8: aa_sdss2003_optimized | M8: galspecindx | N8: 62570496 | O8: 60 MB | P8: 1304 kB | Q8: 496 kB | R8: =IF(ISNUMBER(SEARCH("_2x", L8)), "2x", IF(ISNUMBER(SEARCH("_5x", L8)), "5x", IF(ISNUMBER(SEARCH("_10x", L8)), "10x", "1x"))) -> 1x | V8: 1 | Y8: 1 | AB8: =IF(S8=1,$N8,"") | AC8: =IF(T8=1,$N8,"") | AE8: =IF(V8=1,$N8,"") -> 62570496 | AF8: =IF(W8=1,$N8,"") | AH8: =IF(Y8=1,$N8,"") -> 62570496 | AI8: =IF(Z8=1,$N8,"") | AJ8: =IF(AA8=1,$N8,"")
A9: Scale | B9: $D_1$ | C9: $D_1^{\alpha}$ | D9: $D_2$ | E9: $D_2^{\alpha}$ | F9: $D_2^{\beta}$ | G9: $D_3$ | H9: $D_3^{\alpha}$ | I9: $D_3^{\beta}$ | J9: $D_3^{\gamma}$ | L9: aa_sdss2003_optimized | M9: photoobjall_galaxy | N9: 49152 | O9: 48 kB | P9: 8192 bytes | Q9: 32 kB | R9: =IF(ISNUMBER(SEARCH("_2x", L9)), "2x", IF(ISNUMBER(SEARCH("_5x", L9)), "5x", IF(ISNUMBER(SEARCH("_10x", L9)), "10x", "1x"))) -> 1x | T9: 1 | V9: 1 | Y9: 1 | AB9: =IF(S9=1,$N9,"") | AC9: =IF(T9=1,$N9,"") -> 49152 | AE9: =IF(V9=1,$N9,"") -> 49152 | AF9: =IF(W9=1,$N9,"") | AH9: =IF(Y9=1,$N9,"") -> 49152 | AI9: =IF(Z9=1,$N9,"") | AJ9: =IF(AA9=1,$N9,"")
A10: 1x | B10: =B3/1024/1024 -> 682.64062 | C10: =C3/1024/1024 -> 704.39844 | D10: =D3/1024/1024 -> 848.875 | E10: =E3/1024/1024 -> 875.33594 | F10: =F3/1024/1024 -> 852.53125 | G10: =G3/1024/1024 -> 885.39062 | H10: =H3/1024/1024 -> 891.57812 | I10: =I3/1024/1024 -> 882.42188 | J10: =J3/1024/1024 -> 878.27344 | L10: aa_sdss2003_optimized | M10: photoobjall_galaxycomplementary | N10: 73728 | O10: 72 kB | P10: 8192 bytes | Q10: 16 kB | R10: =IF(ISNUMBER(SEARCH("_2x", L10)), "2x", IF(ISNUMBER(SEARCH("_5x", L10)), "5x", IF(ISNUMBER(SEARCH("_10x", L10)), "10x", "1x"))) -> 1x | T10: 1 | V10: 1 | Y10: 1 | AB10: =IF(S10=1,$N10,"") | AC10: =IF(T10=1,$N10,"") -> 73728 | AE10: =IF(V10=1,$N10,"") -> 73728 | AF10: =IF(W10=1,$N10,"") | AH10: =IF(Y10=1,$N10,"") -> 73728 | AI10: =IF(Z10=1,$N10,"") | AJ10: =IF(AA10=1,$N10,"")
A11: 2x | B11: =B4/1024/1024 -> 1364.9453 | C11: =C4/1024/1024 -> 1408.2188 | D11: =D4/1024/1024 -> 1599.7188 | E11: =E4/1024/1024 -> 1652.3047 | F11: =F4/1024/1024 -> 1606.6172 | G11: =G4/1024/1024 -> 1672.4531 | H11: =H4/1024/1024 -> 1684.6562 | I11: =I4/1024/1024 -> 1666.1953 | J11: =J4/1024/1024 -> 1665.1719 | L11: aa_sdss2003_optimized | M11: photoobjall_other | N11: 384458752 | O11: 367 MB | P11: 3648 kB | Q11: 3296 kB | R11: =IF(ISNUMBER(SEARCH("_2x", L11)), "2x", IF(ISNUMBER(SEARCH("_5x", L11)), "5x", IF(ISNUMBER(SEARCH("_10x", L11)), "10x", "1x"))) -> 1x | T11: 1 | V11: 1 | Y11: 1 | AB11: =IF(S11=1,$N11,"") | AC11: =IF(T11=1,$N11,"") -> 384458752 | AE11: =IF(V11=1,$N11,"") -> 384458752 | AF11: =IF(W11=1,$N11,"") | AH11: =IF(Y11=1,$N11,"") -> 384458752 | AI11: =IF(Z11=1,$N11,"") | AJ11: =IF(AA11=1,$N11,"")
A12: 5x | B12: =B5/1024/1024 -> 3411.8984 | C12: =C5/1024/1024 -> 3519.5859 | D12: =D5/1024/1024 -> 3852.3516 | E12: =E5/1024/1024 -> 3983.1719 | F12: =F5/1024/1024 -> 3869 | G12: =G5/1024/1024 -> 4035.3203 | H12: =H5/1024/1024 -> 4065.3516 | I12: =I5/1024/1024 -> 4019.1797 | J12: =J5/1024/1024 -> 4027.7969 | L12: aa_sdss2003_optimized | M12: photoobjall_primary | N12: 22929408 | O12: 22 MB | P12: 20 MB | Q12: 2040 kB | R12: =IF(ISNUMBER(SEARCH("_2x", L12)), "2x", IF(ISNUMBER(SEARCH("_5x", L12)), "5x", IF(ISNUMBER(SEARCH("_10x", L12)), "10x", "1x"))) -> 1x | T12: 1 | V12: 1 | Y12: 1 | AB12: =IF(S12=1,$N12,"") | AC12: =IF(T12=1,$N12,"") -> 22929408 | AE12: =IF(V12=1,$N12,"") -> 22929408 | AF12: =IF(W12=1,$N12,"") | AH12: =IF(Y12=1,$N12,"") -> 22929408 | AI12: =IF(Z12=1,$N12,"") | AJ12: =IF(AA12=1,$N12,"")
